pytest tests/
(base) PS D:\side_projects\Side-projects\ai_agent_project> pytest tests/
C:\Users\USER\anaconda3\Lib\site-packages\pytest_asyncio\plugin.py:207: PytestDeprecationWarning: The configuration option "asyncio_default_fixture_loop_scope" is unset.
The event loop scope for asynchronous fixtures will default to the fixture caching scope. Future versions of pytest-asyncio will default the loop scope for asynchronous fixtures to function scope. Set the default fixture l
oop scope explicitly in order to avoid unexpected behavior in the future. Valid fixture loop scopes are: "function", "class", "module", "package", "session"                                                                  
  warnings.warn(PytestDeprecationWarning(_DEFAULT_FIXTURE_LOOP_SCOPE_UNSET))
==================================================================================================== test session starts ====================================================================================================
platform win32 -- Python 3.12.3, pytest-8.3.4, pluggy-1.5.0
PyQt5 5.15.11 -- Qt runtime 5.15.2 -- Qt compiled 5.15.2
rootdir: D:\side_projects\Side-projects\ai_agent_project
configfile: pyproject.toml
plugins: anyio-4.8.0, dash-2.18.1, asyncio-0.25.0, cov-6.0.0, json-report-1.5.0, metadata-3.1.1, qt-4.4.0, xdist-3.6.1, requests-mock-1.12.1
asyncio: mode=Mode.STRICT, asyncio_default_fixture_loop_scope=None
collected 69 items / 22 errors

========================================================================================================== ERRORS ===========================================================================================================
_________________________________________________________________________________________ ERROR collecting tests/test_AgentActor.py _________________________________________________________________________________________ 
tests\test_AgentActor.py:4: in <module>
    from ai_engine.models.memory.memory_manager import MemoryManager
ai_engine\models\memory\__init__.py:2: in <module>
    from .memory_manager import MemoryManager
ai_engine\models\memory\memory_manager.py:4: in <module>
    import nltk
C:\Users\USER\anaconda3\Lib\site-packages\nltk\__init__.py:133: in <module>
    from nltk.collocations import *
C:\Users\USER\anaconda3\Lib\site-packages\nltk\collocations.py:36: in <module>
    from nltk.metrics import (
C:\Users\USER\anaconda3\Lib\site-packages\nltk\metrics\__init__.py:18: in <module>
    from nltk.metrics.association import (
C:\Users\USER\anaconda3\Lib\site-packages\nltk\metrics\association.py:26: in <module>
    from scipy.stats import fisher_exact
C:\Users\USER\anaconda3\Lib\site-packages\scipy\stats\__init__.py:606: in <module>
    from ._stats_py import *
C:\Users\USER\anaconda3\Lib\site-packages\scipy\stats\_stats_py.py:37: in <module>
    from scipy import sparse
<frozen importlib._bootstrap>:1412: in _handle_fromlist
    ???
C:\Users\USER\anaconda3\Lib\site-packages\scipy\__init__.py:134: in __getattr__
    return _importlib.import_module(f'scipy.{name}')
C:\Users\USER\anaconda3\Lib\importlib\__init__.py:90: in import_module
    return _bootstrap._gcd_import(name[level:], package, level)
C:\Users\USER\anaconda3\Lib\site-packages\scipy\sparse\__init__.py:297: in <module>
    from ._lil import *
C:\Users\USER\anaconda3\Lib\site-packages\scipy\sparse\_lil.py:17: in <module>
    from . import _csparsetools
scipy\\sparse\\_csparsetools.pyx:1: in init _csparsetools
    ???
E   ValueError: numpy.dtype size changed, may indicate binary incompatibility. Expected 96 from C header, got 88 from PyObject
______________________________________________________________________________________ ERROR collecting tests/test_agent_dispatcher.py ______________________________________________________________________________________ 
ImportError while importing test module 'D:\side_projects\Side-projects\ai_agent_project\tests\test_agent_dispatcher.py'.
Hint: make sure your test modules/packages have valid Python names.
Traceback:
C:\Users\USER\anaconda3\Lib\importlib\__init__.py:90: in import_module
    return _bootstrap._gcd_import(name[level:], package, level)
tests\test_agent_dispatcher.py:6: in <module>
    from agents.AgentDispatcher import AgentDispatcher
agents\AgentDispatcher.py:7: in <module>
    from agents.core.professor_synapse_agent import ProfessorSynapseAgent
agents\core\professor_synapse_agent.py:5: in <module>
    from agents.core.api_client import APIClient  # Handles real-time lookups
E   ModuleNotFoundError: No module named 'agents.core.api_client'
_______________________________________________________________________________________ ERROR collecting tests/test_agent_registry.py _______________________________________________________________________________________ 
ImportError while importing test module 'D:\side_projects\Side-projects\ai_agent_project\tests\test_agent_registry.py'.
Hint: make sure your test modules/packages have valid Python names.
Traceback:
C:\Users\USER\anaconda3\Lib\importlib\__init__.py:90: in import_module
    return _bootstrap._gcd_import(name[level:], package, level)
tests\test_agent_registry.py:4: in <module>
    from agents.core.agent_registry import AgentRegistry
E   ModuleNotFoundError: No module named 'agents.core.agent_registry'
___________________________________________________________________________________ ERROR collecting tests/test_ai_confidence_manager.py ____________________________________________________________________________________ 
C:\Users\USER\AppData\Roaming\Python\Python312\site-packages\_pytest\python.py:493: in importtestmodule
    mod = import_path(
C:\Users\USER\AppData\Roaming\Python\Python312\site-packages\_pytest\pathlib.py:587: in import_path
    importlib.import_module(module_name)
C:\Users\USER\anaconda3\Lib\importlib\__init__.py:90: in import_module
    return _bootstrap._gcd_import(name[level:], package, level)
<frozen importlib._bootstrap>:1387: in _gcd_import
    ???
<frozen importlib._bootstrap>:1360: in _find_and_load
    ???
<frozen importlib._bootstrap>:1331: in _find_and_load_unlocked
    ???
<frozen importlib._bootstrap>:935: in _load_unlocked
    ???
C:\Users\USER\AppData\Roaming\Python\Python312\site-packages\_pytest\assertion\rewrite.py:175: in exec_module
    source_stat, co = _rewrite_test(fn, self.config)
C:\Users\USER\AppData\Roaming\Python\Python312\site-packages\_pytest\assertion\rewrite.py:355: in _rewrite_test
    tree = ast.parse(source, filename=strfn)
C:\Users\USER\anaconda3\Lib\ast.py:52: in parse
    return compile(source, filename, mode, flags,
E     File "D:\side_projects\Side-projects\ai_agent_project\tests\test_ai_confidence_manager.py", line 13
E       def setUp(self):"""Sets up an instance of AIConfidenceManager for testing."""""""""""""""""""
E                                                                                                   ^
E   SyntaxError: unterminated string literal (detected at line 13)
_____________________________________________________________________________________ ERROR collecting tests/test_ai_patch_optimizer.py _____________________________________________________________________________________
C:\Users\USER\AppData\Roaming\Python\Python312\site-packages\_pytest\python.py:493: in importtestmodule
    mod = import_path(
C:\Users\USER\AppData\Roaming\Python\Python312\site-packages\_pytest\pathlib.py:587: in import_path
    importlib.import_module(module_name)
C:\Users\USER\anaconda3\Lib\importlib\__init__.py:90: in import_module
    return _bootstrap._gcd_import(name[level:], package, level)
<frozen importlib._bootstrap>:1387: in _gcd_import
    ???
<frozen importlib._bootstrap>:1360: in _find_and_load
    ???
<frozen importlib._bootstrap>:1331: in _find_and_load_unlocked
    ???
<frozen importlib._bootstrap>:935: in _load_unlocked
    ???
C:\Users\USER\AppData\Roaming\Python\Python312\site-packages\_pytest\assertion\rewrite.py:175: in exec_module
    source_stat, co = _rewrite_test(fn, self.config)
C:\Users\USER\AppData\Roaming\Python\Python312\site-packages\_pytest\assertion\rewrite.py:355: in _rewrite_test
    tree = ast.parse(source, filename=strfn)
C:\Users\USER\anaconda3\Lib\ast.py:52: in parse
    return compile(source, filename, mode, flags,
E     File "D:\side_projects\Side-projects\ai_agent_project\tests\test_ai_patch_optimizer.py", line 12
E       def setUp(self):"""Set up an instance of AIPatchOptimizer for testing."""""""""""""""""""
E                                                                                               ^
E   SyntaxError: unterminated string literal (detected at line 12)
___________________________________________________________________________________ ERROR collecting tests/test_ai_patch_retry_manager.py ___________________________________________________________________________________ 
C:\Users\USER\AppData\Roaming\Python\Python312\site-packages\_pytest\python.py:493: in importtestmodule
    mod = import_path(
C:\Users\USER\AppData\Roaming\Python\Python312\site-packages\_pytest\pathlib.py:587: in import_path
    importlib.import_module(module_name)
C:\Users\USER\anaconda3\Lib\importlib\__init__.py:90: in import_module
    return _bootstrap._gcd_import(name[level:], package, level)
<frozen importlib._bootstrap>:1387: in _gcd_import
    ???
<frozen importlib._bootstrap>:1360: in _find_and_load
    ???
<frozen importlib._bootstrap>:1331: in _find_and_load_unlocked
    ???
<frozen importlib._bootstrap>:935: in _load_unlocked
    ???
C:\Users\USER\AppData\Roaming\Python\Python312\site-packages\_pytest\assertion\rewrite.py:175: in exec_module
    source_stat, co = _rewrite_test(fn, self.config)
C:\Users\USER\AppData\Roaming\Python\Python312\site-packages\_pytest\assertion\rewrite.py:355: in _rewrite_test
    tree = ast.parse(source, filename=strfn)
C:\Users\USER\anaconda3\Lib\ast.py:52: in parse
    return compile(source, filename, mode, flags,
E     File "D:\side_projects\Side-projects\ai_agent_project\tests\test_ai_patch_retry_manager.py", line 13
E       def setUp(self):""" """ """ """"""""""""""""""
E   IndentationError: unexpected indent
__________________________________________________________________________________ ERROR collecting tests/test_ai_patch_review_manager.py ___________________________________________________________________________________ 
C:\Users\USER\AppData\Roaming\Python\Python312\site-packages\_pytest\python.py:493: in importtestmodule
    mod = import_path(
C:\Users\USER\AppData\Roaming\Python\Python312\site-packages\_pytest\pathlib.py:587: in import_path
    importlib.import_module(module_name)
C:\Users\USER\anaconda3\Lib\importlib\__init__.py:90: in import_module
    return _bootstrap._gcd_import(name[level:], package, level)
<frozen importlib._bootstrap>:1387: in _gcd_import
    ???
<frozen importlib._bootstrap>:1360: in _find_and_load
    ???
<frozen importlib._bootstrap>:1331: in _find_and_load_unlocked
    ???
<frozen importlib._bootstrap>:935: in _load_unlocked
    ???
C:\Users\USER\AppData\Roaming\Python\Python312\site-packages\_pytest\assertion\rewrite.py:175: in exec_module
    source_stat, co = _rewrite_test(fn, self.config)
C:\Users\USER\AppData\Roaming\Python\Python312\site-packages\_pytest\assertion\rewrite.py:355: in _rewrite_test
    tree = ast.parse(source, filename=strfn)
C:\Users\USER\anaconda3\Lib\ast.py:52: in parse
    return compile(source, filename, mode, flags,
E     File "D:\side_projects\Side-projects\ai_agent_project\tests\test_ai_patch_review_manager.py", line 15
E       """ """    Unit tests for the AIPatchReviewManager class. """    """ """    def setUp(self):"""FIXED_PLACEHOLDER"""        """ """        Sets up an instance of AIPatchReviewManager for testing."""        """ """  
      self.manager = AIPatchReviewManager()"""        self.error_signature = "example_error_signature"""        self.test_patch = "--- a/code.py\n+++ b/code.py\n@@ -1 +1 @@\n- old code\n+ fixed code"""FIXED_PLACEHOLDER""" 
""" """"""""""""""""""
E                  ^^^^
E   SyntaxError: invalid syntax
_______________________________________________________________________________________ ERROR collecting tests/test_ai_patch_utils.py _______________________________________________________________________________________ 
C:\Users\USER\AppData\Roaming\Python\Python312\site-packages\_pytest\python.py:493: in importtestmodule
    mod = import_path(
C:\Users\USER\AppData\Roaming\Python\Python312\site-packages\_pytest\pathlib.py:587: in import_path
    importlib.import_module(module_name)
C:\Users\USER\anaconda3\Lib\importlib\__init__.py:90: in import_module
    return _bootstrap._gcd_import(name[level:], package, level)
<frozen importlib._bootstrap>:1387: in _gcd_import
    ???
<frozen importlib._bootstrap>:1360: in _find_and_load
    ???
<frozen importlib._bootstrap>:1331: in _find_and_load_unlocked
    ???
<frozen importlib._bootstrap>:935: in _load_unlocked
    ???
C:\Users\USER\AppData\Roaming\Python\Python312\site-packages\_pytest\assertion\rewrite.py:175: in exec_module
    source_stat, co = _rewrite_test(fn, self.config)
C:\Users\USER\AppData\Roaming\Python\Python312\site-packages\_pytest\assertion\rewrite.py:355: in _rewrite_test
    tree = ast.parse(source, filename=strfn)
C:\Users\USER\anaconda3\Lib\ast.py:52: in parse
    return compile(source, filename, mode, flags,
E     File "D:\side_projects\Side-projects\ai_agent_project\tests\test_ai_patch_utils.py", line 43
E       file_content= "def test_function():
E                     ^
E   SyntaxError: unterminated string literal (detected at line 43)
____________________________________________________________________________________ ERROR collecting tests/test_ai_rollback_analysis.py ____________________________________________________________________________________ 
C:\Users\USER\AppData\Roaming\Python\Python312\site-packages\_pytest\python.py:493: in importtestmodule
    mod = import_path(
C:\Users\USER\AppData\Roaming\Python\Python312\site-packages\_pytest\pathlib.py:587: in import_path
    importlib.import_module(module_name)
C:\Users\USER\anaconda3\Lib\importlib\__init__.py:90: in import_module
    return _bootstrap._gcd_import(name[level:], package, level)
<frozen importlib._bootstrap>:1387: in _gcd_import
    ???
<frozen importlib._bootstrap>:1360: in _find_and_load
    ???
<frozen importlib._bootstrap>:1331: in _find_and_load_unlocked
    ???
<frozen importlib._bootstrap>:935: in _load_unlocked
    ???
C:\Users\USER\AppData\Roaming\Python\Python312\site-packages\_pytest\assertion\rewrite.py:175: in exec_module
    source_stat, co = _rewrite_test(fn, self.config)
C:\Users\USER\AppData\Roaming\Python\Python312\site-packages\_pytest\assertion\rewrite.py:355: in _rewrite_test
    tree = ast.parse(source, filename=strfn)
C:\Users\USER\anaconda3\Lib\ast.py:52: in parse
    return compile(source, filename, mode, flags,
E     File "D:\side_projects\Side-projects\ai_agent_project\tests\test_ai_rollback_analysis.py", line 37
E       def test_refine_patches_success(self, mock_analyze_patches, mock_refine_patch):""" """        Test refinement of AI-correctable patches."""        """ """        result = self.manager.refine_patches(self.error_sign
ature)"""        self.assertTrue(result)"""FIXED_PLACEHOLDER"""    @patch("agents.core.AIRollbackAnalysis.AIRollbackAnalysis.analyze_failed_patches", return_value=([], [], []))""""""""""")"""")"")                          E
                                                                                                                                                                                                  ^
E   SyntaxError: unterminated string literal (detected at line 37)
_________________________________________________________________________________________ ERROR collecting tests/test_auto_fixer.py _________________________________________________________________________________________ 
C:\Users\USER\AppData\Roaming\Python\Python312\site-packages\_pytest\python.py:493: in importtestmodule
    mod = import_path(
C:\Users\USER\AppData\Roaming\Python\Python312\site-packages\_pytest\pathlib.py:587: in import_path
    importlib.import_module(module_name)
C:\Users\USER\anaconda3\Lib\importlib\__init__.py:90: in import_module
    return _bootstrap._gcd_import(name[level:], package, level)
<frozen importlib._bootstrap>:1387: in _gcd_import
    ???
<frozen importlib._bootstrap>:1360: in _find_and_load
    ???
<frozen importlib._bootstrap>:1331: in _find_and_load_unlocked
    ???
<frozen importlib._bootstrap>:935: in _load_unlocked
    ???
C:\Users\USER\AppData\Roaming\Python\Python312\site-packages\_pytest\assertion\rewrite.py:175: in exec_module
    source_stat, co = _rewrite_test(fn, self.config)
C:\Users\USER\AppData\Roaming\Python\Python312\site-packages\_pytest\assertion\rewrite.py:355: in _rewrite_test
    tree = ast.parse(source, filename=strfn)
C:\Users\USER\anaconda3\Lib\ast.py:52: in parse
    return compile(source, filename, mode, flags,
E     File "D:\side_projects\Side-projects\ai_agent_project\tests\test_auto_fixer.py", line 14
E       def setUp(self):"""Sets up an instance of AutoFixer for testing."""""""""""""""""""
E                                                                                         ^
E   SyntaxError: unterminated string literal (detected at line 14)
________________________________________________________________________________________ ERROR collecting tests/test_custom_agent.py ________________________________________________________________________________________ 
C:\Users\USER\AppData\Roaming\Python\Python312\site-packages\_pytest\python.py:493: in importtestmodule
    mod = import_path(
C:\Users\USER\AppData\Roaming\Python\Python312\site-packages\_pytest\pathlib.py:587: in import_path
    importlib.import_module(module_name)
C:\Users\USER\anaconda3\Lib\importlib\__init__.py:90: in import_module
    return _bootstrap._gcd_import(name[level:], package, level)
<frozen importlib._bootstrap>:1387: in _gcd_import
    ???
<frozen importlib._bootstrap>:1360: in _find_and_load
    ???
<frozen importlib._bootstrap>:1331: in _find_and_load_unlocked
    ???
<frozen importlib._bootstrap>:935: in _load_unlocked
    ???
C:\Users\USER\AppData\Roaming\Python\Python312\site-packages\_pytest\assertion\rewrite.py:175: in exec_module
    source_stat, co = _rewrite_test(fn, self.config)
C:\Users\USER\AppData\Roaming\Python\Python312\site-packages\_pytest\assertion\rewrite.py:355: in _rewrite_test
    tree = ast.parse(source, filename=strfn)
C:\Users\USER\anaconda3\Lib\ast.py:52: in parse
    return compile(source, filename, mode, flags,
E     File "D:\side_projects\Side-projects\ai_agent_project\tests\test_custom_agent.py", line 13
E       def setUp(self):"""Set up a fresh instance of CustomAgent for each test."""""""""""""""""""
E                                                                                                 ^
E   SyntaxError: unterminated string literal (detected at line 13)
___________________________________________________________________________________ ERROR collecting tests/test_debug_agent_auto_fixer.py ___________________________________________________________________________________ 
ImportError while importing test module 'D:\side_projects\Side-projects\ai_agent_project\tests\test_debug_agent_auto_fixer.py'.
Hint: make sure your test modules/packages have valid Python names.
Traceback:
C:\Users\USER\anaconda3\Lib\importlib\__init__.py:90: in import_module
    return _bootstrap._gcd_import(name[level:], package, level)
tests\test_debug_agent_auto_fixer.py:7: in <module>
    from ai_engine.models.debugger.debug_agent_auto_fixer import DebugAgentAutoFixer
ai_engine\models\debugger\debug_agent_auto_fixer.py:7: in <module>
    from debugging_strategy import DebuggingStrategy
E   ModuleNotFoundError: No module named 'debugging_strategy'
_____________________________________________________________________________________ ERROR collecting tests/test_debug_agent_utils.py ______________________________________________________________________________________ 
C:\Users\USER\AppData\Roaming\Python\Python312\site-packages\_pytest\python.py:493: in importtestmodule
    mod = import_path(
C:\Users\USER\AppData\Roaming\Python\Python312\site-packages\_pytest\pathlib.py:587: in import_path
    importlib.import_module(module_name)
C:\Users\USER\anaconda3\Lib\importlib\__init__.py:90: in import_module
    return _bootstrap._gcd_import(name[level:], package, level)
<frozen importlib._bootstrap>:1387: in _gcd_import
    ???
<frozen importlib._bootstrap>:1360: in _find_and_load
    ???
<frozen importlib._bootstrap>:1331: in _find_and_load_unlocked
    ???
<frozen importlib._bootstrap>:935: in _load_unlocked
    ???
C:\Users\USER\AppData\Roaming\Python\Python312\site-packages\_pytest\assertion\rewrite.py:175: in exec_module
    source_stat, co = _rewrite_test(fn, self.config)
C:\Users\USER\AppData\Roaming\Python\Python312\site-packages\_pytest\assertion\rewrite.py:355: in _rewrite_test
    tree = ast.parse(source, filename=strfn)
C:\Users\USER\anaconda3\Lib\ast.py:52: in parse
    return compile(source, filename, mode, flags,
E     File "D:\side_projects\Side-projects\ai_agent_project\tests\test_debug_agent_utils.py", line 43
E       """f __name__ == "__main__": """"""""""""""""""
E                                                   ^
E   SyntaxError: unterminated triple-quoted string literal (detected at line 44)
_______________________________________________________________________________________ ERROR collecting tests/test_debugger_agent.py _______________________________________________________________________________________ 
ImportError while importing test module 'D:\side_projects\Side-projects\ai_agent_project\tests\test_debugger_agent.py'.
Hint: make sure your test modules/packages have valid Python names.
Traceback:
C:\Users\USER\anaconda3\Lib\importlib\__init__.py:90: in import_module
    return _bootstrap._gcd_import(name[level:], package, level)
tests\test_debugger_agent.py:4: in <module>
    from ai_model_manager import AIModelManager
E   ModuleNotFoundError: No module named 'ai_model_manager'
________________________________________________________________________________________ ERROR collecting tests/test_debugger_cli.py ________________________________________________________________________________________ 
ImportError while importing test module 'D:\side_projects\Side-projects\ai_agent_project\tests\test_debugger_cli.py'.
Hint: make sure your test modules/packages have valid Python names.
Traceback:
C:\Users\USER\anaconda3\Lib\importlib\__init__.py:90: in import_module
    return _bootstrap._gcd_import(name[level:], package, level)
tests\test_debugger_cli.py:7: in <module>
    from ai_engine.models.debugger.debugger_cli import AI_PERFORMANCE_FILE, DebuggerCLI
ai_engine\models\debugger\debugger_cli.py:5: in <module>
    from ai_engine.models.debugger.debugger_core import DebuggerCore
ai_engine\models\debugger\debugger_core.py:3: in <module>
    from debugger.test_runner import TestRunner
E   ModuleNotFoundError: No module named 'debugger.test_runner'
_______________________________________________________________________________________ ERROR collecting tests/test_debugger_core.py ________________________________________________________________________________________ 
ImportError while importing test module 'D:\side_projects\Side-projects\ai_agent_project\tests\test_debugger_core.py'.
Hint: make sure your test modules/packages have valid Python names.
Traceback:
C:\Users\USER\anaconda3\Lib\importlib\__init__.py:90: in import_module
    return _bootstrap._gcd_import(name[level:], package, level)
tests\test_debugger_core.py:7: in <module>
    from ai_engine.models.debugger.debugger_core import DebuggerCore
ai_engine\models\debugger\debugger_core.py:3: in <module>
    from debugger.test_runner import TestRunner
E   ModuleNotFoundError: No module named 'debugger.test_runner'
_____________________________________________________________________________________ ERROR collecting tests/test_debugger_reporter.py ______________________________________________________________________________________ 
ImportError while importing test module 'D:\side_projects\Side-projects\ai_agent_project\tests\test_debugger_reporter.py'.
Hint: make sure your test modules/packages have valid Python names.
Traceback:
C:\Users\USER\anaconda3\Lib\importlib\__init__.py:90: in import_module
    return _bootstrap._gcd_import(name[level:], package, level)
tests\test_debugger_reporter.py:7: in <module>
    from ai_engine.models.debugger.debugger_reporter import REPORT_FILE, DebuggerReporter
ai_engine\models\debugger\debugger_reporter.py:6: in <module>
    from email_reporter import EmailReporter  # Optional email notifications
E   ModuleNotFoundError: No module named 'email_reporter'
______________________________________________________________________________________ ERROR collecting tests/test_debugger_runner.py _______________________________________________________________________________________ 
tests\test_debugger_runner.py:6: in <module>
    from ai_engine.models.debugger.debugger_runner import DebuggerRunner
ai_engine\models\debugger\debugger_runner.py:5: in <module>
    from ai_engine.models.debugger.auto_fixer import AutoFixer
ai_engine\models\debugger\auto_fixer.py:6: in <module>
    from ai_engine.models.debugger.learning_db import LearningDB
ai_engine\models\debugger\learning_db.py:9: in <module>
    class LearningDB:
ai_engine\models\debugger\learning_db.py:30: in LearningDB
    def get_known_fix(self, error_sig: str) -> Optional[str]:
E   NameError: name 'Optional' is not defined
_______________________________________________________________________________________ ERROR collecting tests/test_deepseek_model.py _______________________________________________________________________________________
ImportError while importing test module 'D:\side_projects\Side-projects\ai_agent_project\tests\test_deepseek_model.py'.
Hint: make sure your test modules/packages have valid Python names.
Traceback:
C:\Users\USER\anaconda3\Lib\importlib\__init__.py:90: in import_module
    return _bootstrap._gcd_import(name[level:], package, level)
tests\test_deepseek_model.py:6: in <module>
    from agents.AgentDispatcher import AgentDispatcher
agents\AgentDispatcher.py:7: in <module>
    from agents.core.professor_synapse_agent import ProfessorSynapseAgent
agents\core\professor_synapse_agent.py:5: in <module>
    from agents.core.api_client import APIClient  # Handles real-time lookups
E   ModuleNotFoundError: No module named 'agents.core.api_client'
_________________________________________________________________________________________ ERROR collecting tests/test_dispatcher.py _________________________________________________________________________________________
ImportError while importing test module 'D:\side_projects\Side-projects\ai_agent_project\tests\test_dispatcher.py'.
Hint: make sure your test modules/packages have valid Python names.
Traceback:
C:\Users\USER\anaconda3\Lib\importlib\__init__.py:90: in import_module
    return _bootstrap._gcd_import(name[level:], package, level)
tests\test_dispatcher.py:4: in <module>
    from agents.AgentDispatcher import AgentDispatcher
agents\AgentDispatcher.py:7: in <module>
    from agents.core.professor_synapse_agent import ProfessorSynapseAgent
agents\core\professor_synapse_agent.py:5: in <module>
    from agents.core.api_client import APIClient  # Handles real-time lookups
E   ModuleNotFoundError: No module named 'agents.core.api_client'
_______________________________________________________________________________________ ERROR collecting tests/test_journal_agent.py ________________________________________________________________________________________ 
tests\test_journal_agent.py:7: in <module>
    from agents.custom_agent import CustomAgent
agents\custom_agent.py:1: in <module>
    from ai_engine.models.memory.context_manager import ContextManager
ai_engine\models\memory\__init__.py:2: in <module>
    from .memory_manager import MemoryManager
ai_engine\models\memory\memory_manager.py:4: in <module>
    import nltk
C:\Users\USER\anaconda3\Lib\site-packages\nltk\__init__.py:133: in <module>
    from nltk.collocations import *
C:\Users\USER\anaconda3\Lib\site-packages\nltk\collocations.py:36: in <module>
    from nltk.metrics import (
C:\Users\USER\anaconda3\Lib\site-packages\nltk\metrics\__init__.py:18: in <module>
    from nltk.metrics.association import (
C:\Users\USER\anaconda3\Lib\site-packages\nltk\metrics\association.py:26: in <module>
    from scipy.stats import fisher_exact
C:\Users\USER\anaconda3\Lib\site-packages\scipy\stats\__init__.py:606: in <module>
    from ._stats_py import *
C:\Users\USER\anaconda3\Lib\site-packages\scipy\stats\_stats_py.py:37: in <module>
    from scipy import sparse
<frozen importlib._bootstrap>:1412: in _handle_fromlist
    ???
C:\Users\USER\anaconda3\Lib\site-packages\scipy\__init__.py:134: in __getattr__
    return _importlib.import_module(f'scipy.{name}')
C:\Users\USER\anaconda3\Lib\importlib\__init__.py:90: in import_module
    return _bootstrap._gcd_import(name[level:], package, level)
C:\Users\USER\anaconda3\Lib\site-packages\scipy\sparse\__init__.py:297: in <module>
    from ._lil import *
C:\Users\USER\anaconda3\Lib\site-packages\scipy\sparse\_lil.py:17: in <module>
    from . import _csparsetools
scipy\\sparse\\_csparsetools.pyx:1: in init _csparsetools
    ???
E   ValueError: numpy.dtype size changed, may indicate binary incompatibility. Expected 96 from C header, got 88 from PyObject
________________________________________________________________________________________ ERROR collecting tests/test_openai_model.py ________________________________________________________________________________________
tests\test_openai_model.py:8: in <module>
    from agents.custom_agent import CustomAgent
agents\custom_agent.py:1: in <module>
    from ai_engine.models.memory.context_manager import ContextManager
ai_engine\models\memory\__init__.py:2: in <module>
    from .memory_manager import MemoryManager
ai_engine\models\memory\memory_manager.py:4: in <module>
    import nltk
C:\Users\USER\anaconda3\Lib\site-packages\nltk\__init__.py:133: in <module>
    from nltk.collocations import *
C:\Users\USER\anaconda3\Lib\site-packages\nltk\collocations.py:36: in <module>
    from nltk.metrics import (
C:\Users\USER\anaconda3\Lib\site-packages\nltk\metrics\__init__.py:18: in <module>
    from nltk.metrics.association import (
C:\Users\USER\anaconda3\Lib\site-packages\nltk\metrics\association.py:26: in <module>
    from scipy.stats import fisher_exact
C:\Users\USER\anaconda3\Lib\site-packages\scipy\stats\__init__.py:606: in <module>
    from ._stats_py import *
C:\Users\USER\anaconda3\Lib\site-packages\scipy\stats\_stats_py.py:37: in <module>
    from scipy import sparse
<frozen importlib._bootstrap>:1412: in _handle_fromlist
    ???
C:\Users\USER\anaconda3\Lib\site-packages\scipy\__init__.py:134: in __getattr__
    return _importlib.import_module(f'scipy.{name}')
C:\Users\USER\anaconda3\Lib\importlib\__init__.py:90: in import_module
    return _bootstrap._gcd_import(name[level:], package, level)
C:\Users\USER\anaconda3\Lib\site-packages\scipy\sparse\__init__.py:297: in <module>
    from ._lil import *
C:\Users\USER\anaconda3\Lib\site-packages\scipy\sparse\_lil.py:17: in <module>
    from . import _csparsetools
scipy\\sparse\\_csparsetools.pyx:1: in init _csparsetools
    ???
E   ValueError: numpy.dtype size changed, may indicate binary incompatibility. Expected 96 from C header, got 88 from PyObject
================================================================================================== short test summary info ================================================================================================== 
ERROR tests/test_AgentActor.py - ValueError: numpy.dtype size changed, may indicate binary incompatibility. Expected 96 from C header, got 88 from PyObject
ERROR tests/test_agent_dispatcher.py
ERROR tests/test_agent_registry.py
ERROR tests/test_ai_confidence_manager.py
ERROR tests/test_ai_patch_optimizer.py
ERROR tests/test_ai_patch_retry_manager.py
ERROR tests/test_ai_patch_review_manager.py
ERROR tests/test_ai_patch_utils.py
ERROR tests/test_ai_rollback_analysis.py
ERROR tests/test_auto_fixer.py
ERROR tests/test_custom_agent.py
ERROR tests/test_debug_agent_auto_fixer.py
ERROR tests/test_debug_agent_utils.py
ERROR tests/test_debugger_agent.py
ERROR tests/test_debugger_cli.py
ERROR tests/test_debugger_core.py
ERROR tests/test_debugger_reporter.py
ERROR tests/test_debugger_runner.py - NameError: name 'Optional' is not defined
ERROR tests/test_deepseek_model.py
ERROR tests/test_dispatcher.py
ERROR tests/test_journal_agent.py - ValueError: numpy.dtype size changed, may indicate binary incompatibility. Expected 96 from C header, got 88 from PyObject
ERROR tests/test_openai_model.py - ValueError: numpy.dtype size changed, may indicate binary incompatibility. Expected 96 from C header, got 88 from PyObject
!!!!!!!!!!!!!!!!!!!!!!!!!!!!!!!!!!!!!!!!!!!!!!!!!!!!!!!!!!!!!!!!!!!!!!!!!!!!!!!!!!!!!!!!! Interrupted: 22 errors during collection !!!!!!!!!!!!!!!!!!!!!!!!!!!!!!!!!!!!!!!!!!!!!!!!!!!!!!!!!!!!!!!!!!!!!!!!!!!!!!!!!!!!!!!!!! 
==================================================================================================== 22 errors in 9.75s =====================================================================================================
