(base) PS D:\side_projects\Side-projects\ai_agent_project> pytest tests/
C:\Users\USER\anaconda3\Lib\site-packages\pytest_asyncio\plugin.py:207: PytestDeprecationWarning: The configuration option "asyncio_default_fixture_loop_scope" is unset.
The event loop scope for asynchronous fixtures will default to the fixture caching scope. Future versions of pytest-asyncio will default the loop scope for asynchronous fixtures to function scope. Set the default fixture loop scope explicitly in order to avoid unexpected behavior in the future. Valid fixture loop scopes are: "function", "class", "module", "package", "session"

  warnings.warn(PytestDeprecationWarning(_DEFAULT_FIXTURE_LOOP_SCOPE_UNSET))
==================================================================================================== test session starts ====================================================================================================
platform win32 -- Python 3.12.3, pytest-8.3.4, pluggy-1.5.0
PyQt5 5.15.11 -- Qt runtime 5.15.2 -- Qt compiled 5.15.2
rootdir: D:\side_projects\Side-projects\ai_agent_project
configfile: pyproject.toml
plugins: anyio-4.8.0, dash-2.18.1, asyncio-0.25.0, cov-6.0.0, json-report-1.5.0, metadata-3.1.1, qt-4.4.0, xdist-3.6.1, requests-mock-1.12.1
asyncio: mode=Mode.STRICT, asyncio_default_fixture_loop_scope=None
collected 77 items / 21 errors

========================================================================================================== ERRORS ===========================================================================================================
_________________________________________________________________________________________ ERROR collecting tests/test_AgentActor.py _________________________________________________________________________________________
tests\test_AgentActor.py:4: in <module>
    from ai_engine.models.memory.memory_manager import MemoryManager
ai_engine\models\memory\__init__.py:2: in <module>
    from .memory_manager import MemoryManager
ai_engine\models\memory\memory_manager.py:4: in <module>
    import nltk
C:\Users\USER\anaconda3\Lib\site-packages\nltk\__init__.py:146: in <module>
    from nltk.chunk import *
C:\Users\USER\anaconda3\Lib\site-packages\nltk\chunk\__init__.py:155: in <module>
    from nltk.chunk.api import ChunkParserI
C:\Users\USER\anaconda3\Lib\site-packages\nltk\chunk\api.py:13: in <module>
    from nltk.chunk.util import ChunkScore
C:\Users\USER\anaconda3\Lib\site-packages\nltk\chunk\util.py:12: in <module>
    from nltk.tag.mapping import map_tag
C:\Users\USER\anaconda3\Lib\site-packages\nltk\tag\__init__.py:70: in <module>
    from nltk.tag.sequential import (
C:\Users\USER\anaconda3\Lib\site-packages\nltk\tag\sequential.py:26: in <module>
    from nltk.classify import NaiveBayesClassifier
C:\Users\USER\anaconda3\Lib\site-packages\nltk\classify\__init__.py:97: in <module>
    from nltk.classify.scikitlearn import SklearnClassifier
C:\Users\USER\anaconda3\Lib\site-packages\nltk\classify\scikitlearn.py:38: in <module>
    from sklearn.feature_extraction import DictVectorizer
C:\Users\USER\anaconda3\Lib\site-packages\sklearn\__init__.py:87: in <module>
    from .base import clone
C:\Users\USER\anaconda3\Lib\site-packages\sklearn\base.py:19: in <module>
    from .utils import _IS_32BIT
C:\Users\USER\anaconda3\Lib\site-packages\sklearn\utils\__init__.py:28: in <module>
    from .murmurhash import murmurhash3_32
sklearn\\utils\\murmurhash.pyx:1: in init sklearn.utils.murmurhash
    ???
E   ValueError: numpy.dtype size changed, may indicate binary incompatibility. Expected 96 from C header, got 88 from PyObject
______________________________________________________________________________________ ERROR collecting tests/test_agent_dispatcher.py ______________________________________________________________________________________ 
ImportError while importing test module 'D:\side_projects\Side-projects\ai_agent_project\tests\test_agent_dispatcher.py'.
Hint: make sure your test modules/packages have valid Python names.
Traceback:
C:\Users\USER\anaconda3\Lib\importlib\__init__.py:90: in import_module
    return _bootstrap._gcd_import(name[level:], package, level)
tests\test_agent_dispatcher.py:9: in <module>
    from agents.AgentDispatcher import AgentDispatcher
agents\AgentDispatcher.py:7: in <module>
    from agents.core.professor_synapse_agent import ProfessorSynapseAgent
agents\core\professor_synapse_agent.py:5: in <module>
    from agents.core.api_client import APIClient  # Handles real-time lookups
E   ModuleNotFoundError: No module named 'agents.core.api_client'
_______________________________________________________________________________________ ERROR collecting tests/test_agent_registry.py _______________________________________________________________________________________ 
ImportError while importing test module 'D:\side_projects\Side-projects\ai_agent_project\tests\test_agent_registry.py'.
Hint: make sure your test modules/packages have valid Python names.
Traceback:
C:\Users\USER\anaconda3\Lib\importlib\__init__.py:90: in import_module
    return _bootstrap._gcd_import(name[level:], package, level)
tests\test_agent_registry.py:5: in <module>
    from agents.core.agent_registry import AgentRegistry
E   ModuleNotFoundError: No module named 'agents.core.agent_registry'
___________________________________________________________________________________ ERROR collecting tests/test_ai_confidence_manager.py ____________________________________________________________________________________ 
ImportError while importing test module 'D:\side_projects\Side-projects\ai_agent_project\tests\test_ai_confidence_manager.py'.
Hint: make sure your test modules/packages have valid Python names.
Traceback:
C:\Users\USER\anaconda3\Lib\importlib\__init__.py:90: in import_module
    return _bootstrap._gcd_import(name[level:], package, level)
tests\test_ai_confidence_manager.py:6: in <module>
    from agents.core.utilities.ai_confidence_manager import (
E   ModuleNotFoundError: No module named 'agents.core.utilities.ai_confidence_manager'
_____________________________________________________________________________________ ERROR collecting tests/test_ai_patch_optimizer.py _____________________________________________________________________________________ 
ImportError while importing test module 'D:\side_projects\Side-projects\ai_agent_project\tests\test_ai_patch_optimizer.py'.
Hint: make sure your test modules/packages have valid Python names.
Traceback:
C:\Users\USER\anaconda3\Lib\importlib\__init__.py:90: in import_module
    return _bootstrap._gcd_import(name[level:], package, level)
tests\test_ai_patch_optimizer.py:4: in <module>
    from agents.core.utilities.ai_patch_optimizer import AIPatchOptimizer
E   ModuleNotFoundError: No module named 'agents.core.utilities.ai_patch_optimizer'
___________________________________________________________________________________ ERROR collecting tests/test_ai_patch_retry_manager.py ___________________________________________________________________________________ 
ImportError while importing test module 'D:\side_projects\Side-projects\ai_agent_project\tests\test_ai_patch_retry_manager.py'.
Hint: make sure your test modules/packages have valid Python names.
Traceback:
C:\Users\USER\anaconda3\Lib\importlib\__init__.py:90: in import_module
    return _bootstrap._gcd_import(name[level:], package, level)
tests\test_ai_patch_retry_manager.py:4: in <module>
    from agents.core.utilities.ai_patch_retry_manager import AIPatchRetryManager
E   ModuleNotFoundError: No module named 'agents.core.utilities.ai_patch_retry_manager'
__________________________________________________________________________________ ERROR collecting tests/test_ai_patch_review_manager.py ___________________________________________________________________________________ 
ImportError while importing test module 'D:\side_projects\Side-projects\ai_agent_project\tests\test_ai_patch_review_manager.py'.
Hint: make sure your test modules/packages have valid Python names.
Traceback:
C:\Users\USER\anaconda3\Lib\importlib\__init__.py:90: in import_module
    return _bootstrap._gcd_import(name[level:], package, level)
tests\test_ai_patch_review_manager.py:6: in <module>
    from agents.core.utilities.ai_patch_review_manager import (
E   ModuleNotFoundError: No module named 'agents.core.utilities.ai_patch_review_manager'
____________________________________________________________________________________ ERROR collecting tests/test_ai_rollback_analysis.py ____________________________________________________________________________________ 
ImportError while importing test module 'D:\side_projects\Side-projects\ai_agent_project\tests\test_ai_rollback_analysis.py'.
Hint: make sure your test modules/packages have valid Python names.
Traceback:
C:\Users\USER\anaconda3\Lib\importlib\__init__.py:90: in import_module
    return _bootstrap._gcd_import(name[level:], package, level)
tests\test_ai_rollback_analysis.py:6: in <module>
    from agents.core.utilities.ai_rollback_analysis import (
E   ModuleNotFoundError: No module named 'agents.core.utilities.ai_rollback_analysis'
_________________________________________________________________________________________ ERROR collecting tests/test_auto_fixer.py _________________________________________________________________________________________ 
ImportError while importing test module 'D:\side_projects\Side-projects\ai_agent_project\tests\test_auto_fixer.py'.
Hint: make sure your test modules/packages have valid Python names.
Traceback:
C:\Users\USER\anaconda3\Lib\importlib\__init__.py:90: in import_module
    return _bootstrap._gcd_import(name[level:], package, level)
tests\test_auto_fixer.py:6: in <module>
    from agents.core.utilities.auto_fixer import AutoFixer
E   ModuleNotFoundError: No module named 'agents.core.utilities.auto_fixer'
________________________________________________________________________________________ ERROR collecting tests/test_custom_agent.py ________________________________________________________________________________________ 
ImportError while importing test module 'D:\side_projects\Side-projects\ai_agent_project\tests\test_custom_agent.py'.
Hint: make sure your test modules/packages have valid Python names.
Traceback:
C:\Users\USER\anaconda3\Lib\importlib\__init__.py:90: in import_module
    return _bootstrap._gcd_import(name[level:], package, level)
tests\test_custom_agent.py:9: in <module>
    from agents.core.models.deepseek_model import DeepSeekModel
E   ModuleNotFoundError: No module named 'agents.core.models'
___________________________________________________________________________________ ERROR collecting tests/test_debug_agent_auto_fixer.py ___________________________________________________________________________________ 
ImportError while importing test module 'D:\side_projects\Side-projects\ai_agent_project\tests\test_debug_agent_auto_fixer.py'.
Hint: make sure your test modules/packages have valid Python names.
Traceback:
C:\Users\USER\anaconda3\Lib\importlib\__init__.py:90: in import_module
    return _bootstrap._gcd_import(name[level:], package, level)
tests\test_debug_agent_auto_fixer.py:7: in <module>
    from ai_engine.models.debugger.debug_agent_auto_fixer import DebugAgentAutoFixer
ai_engine\models\debugger\debug_agent_auto_fixer.py:7: in <module>
    from debugging_strategy import DebuggingStrategy
E   ModuleNotFoundError: No module named 'debugging_strategy'
_____________________________________________________________________________________ ERROR collecting tests/test_debug_agent_utils.py ______________________________________________________________________________________ 
ImportError while importing test module 'D:\side_projects\Side-projects\ai_agent_project\tests\test_debug_agent_utils.py'.
Hint: make sure your test modules/packages have valid Python names.
Traceback:
C:\Users\USER\anaconda3\Lib\importlib\__init__.py:90: in import_module
    return _bootstrap._gcd_import(name[level:], package, level)
tests\test_debug_agent_utils.py:5: in <module>
    from ai_model_manager import AIModelManager
E   ModuleNotFoundError: No module named 'ai_model_manager'
_______________________________________________________________________________________ ERROR collecting tests/test_debugger_agent.py _______________________________________________________________________________________ 
ImportError while importing test module 'D:\side_projects\Side-projects\ai_agent_project\tests\test_debugger_agent.py'.
Hint: make sure your test modules/packages have valid Python names.
Traceback:
C:\Users\USER\anaconda3\Lib\importlib\__init__.py:90: in import_module
    return _bootstrap._gcd_import(name[level:], package, level)
tests\test_debugger_agent.py:7: in <module>
    from agents.core.debugger_agent import DebuggerAgent  # Ensure this exists
E   ModuleNotFoundError: No module named 'agents.core.debugger_agent'
________________________________________________________________________________________ ERROR collecting tests/test_debugger_cli.py ________________________________________________________________________________________ 
ImportError while importing test module 'D:\side_projects\Side-projects\ai_agent_project\tests\test_debugger_cli.py'.
Hint: make sure your test modules/packages have valid Python names.
Traceback:
C:\Users\USER\anaconda3\Lib\importlib\__init__.py:90: in import_module
    return _bootstrap._gcd_import(name[level:], package, level)
tests\test_debugger_cli.py:7: in <module>
    from agents.core.debugger_cli import AI_PERFORMANCE_FILE, DebuggerCLI
E   ModuleNotFoundError: No module named 'agents.core.debugger_cli'
_______________________________________________________________________________________ ERROR collecting tests/test_debugger_core.py ________________________________________________________________________________________ 
ImportError while importing test module 'D:\side_projects\Side-projects\ai_agent_project\tests\test_debugger_core.py'.
Hint: make sure your test modules/packages have valid Python names.
Traceback:
C:\Users\USER\anaconda3\Lib\importlib\__init__.py:90: in import_module
    return _bootstrap._gcd_import(name[level:], package, level)
tests\test_debugger_core.py:7: in <module>
    from agents.core.debugger_core import DebuggerCore
E   ModuleNotFoundError: No module named 'agents.core.debugger_core'
_____________________________________________________________________________________ ERROR collecting tests/test_debugger_reporter.py ______________________________________________________________________________________ 
ImportError while importing test module 'D:\side_projects\Side-projects\ai_agent_project\tests\test_debugger_reporter.py'.
Hint: make sure your test modules/packages have valid Python names.
Traceback:
C:\Users\USER\anaconda3\Lib\importlib\__init__.py:90: in import_module
    return _bootstrap._gcd_import(name[level:], package, level)
tests\test_debugger_reporter.py:7: in <module>
    from ai_engine.models.debugger.debugger_reporter import REPORT_FILE, DebuggerReporter
ai_engine\models\debugger\debugger_reporter.py:6: in <module>
    from email_reporter import EmailReporter  # Optional email notifications
E   ModuleNotFoundError: No module named 'email_reporter'
______________________________________________________________________________________ ERROR collecting tests/test_debugger_runner.py _______________________________________________________________________________________ 
tests\test_debugger_runner.py:6: in <module>
    from ai_engine.models.debugger.debugger_runner import DebuggerRunner
ai_engine\models\debugger\debugger_runner.py:5: in <module>
    from ai_engine.models.debugger.auto_fixer import AutoFixer
ai_engine\models\debugger\auto_fixer.py:6: in <module>
    from ai_engine.models.debugger.learning_db import LearningDB
ai_engine\models\debugger\learning_db.py:9: in <module>
    class LearningDB:
ai_engine\models\debugger\learning_db.py:30: in LearningDB
    def get_known_fix(self, error_sig: str) -> Optional[str]:
E   NameError: name 'Optional' is not defined
_______________________________________________________________________________________ ERROR collecting tests/test_deepseek_model.py _______________________________________________________________________________________ 
ImportError while importing test module 'D:\side_projects\Side-projects\ai_agent_project\tests\test_deepseek_model.py'.
Hint: make sure your test modules/packages have valid Python names.
Traceback:
C:\Users\USER\anaconda3\Lib\importlib\__init__.py:90: in import_module
    return _bootstrap._gcd_import(name[level:], package, level)
tests\test_deepseek_model.py:6: in <module>
    from agents.AgentDispatcher import AgentDispatcher
agents\AgentDispatcher.py:7: in <module>
    from agents.core.professor_synapse_agent import ProfessorSynapseAgent
agents\core\professor_synapse_agent.py:5: in <module>
    from agents.core.api_client import APIClient  # Handles real-time lookups
E   ModuleNotFoundError: No module named 'agents.core.api_client'
_________________________________________________________________________________________ ERROR collecting tests/test_dispatcher.py _________________________________________________________________________________________ 
ImportError while importing test module 'D:\side_projects\Side-projects\ai_agent_project\tests\test_dispatcher.py'.
Hint: make sure your test modules/packages have valid Python names.
Traceback:
C:\Users\USER\anaconda3\Lib\importlib\__init__.py:90: in import_module
    return _bootstrap._gcd_import(name[level:], package, level)
tests\test_dispatcher.py:4: in <module>
    from agents.AgentDispatcher import AgentDispatcher
agents\AgentDispatcher.py:7: in <module>
    from agents.core.professor_synapse_agent import ProfessorSynapseAgent
agents\core\professor_synapse_agent.py:5: in <module>
    from agents.core.api_client import APIClient  # Handles real-time lookups
E   ModuleNotFoundError: No module named 'agents.core.api_client'
_______________________________________________________________________________________ ERROR collecting tests/test_journal_agent.py ________________________________________________________________________________________ 
tests\test_journal_agent.py:7: in <module>
    from agents.custom_agent import CustomAgent
agents\custom_agent.py:1: in <module>
    from ai_engine.models.memory.context_manager import ContextManager
ai_engine\models\memory\__init__.py:2: in <module>
    from .memory_manager import MemoryManager
ai_engine\models\memory\memory_manager.py:4: in <module>
    import nltk
C:\Users\USER\anaconda3\Lib\site-packages\nltk\__init__.py:146: in <module>
    from nltk.chunk import *
C:\Users\USER\anaconda3\Lib\site-packages\nltk\chunk\__init__.py:155: in <module>
    from nltk.chunk.api import ChunkParserI
C:\Users\USER\anaconda3\Lib\site-packages\nltk\chunk\api.py:13: in <module>
    from nltk.chunk.util import ChunkScore
C:\Users\USER\anaconda3\Lib\site-packages\nltk\chunk\util.py:12: in <module>
    from nltk.tag.mapping import map_tag
C:\Users\USER\anaconda3\Lib\site-packages\nltk\tag\__init__.py:70: in <module>
    from nltk.tag.sequential import (
C:\Users\USER\anaconda3\Lib\site-packages\nltk\tag\sequential.py:26: in <module>
    from nltk.classify import NaiveBayesClassifier
C:\Users\USER\anaconda3\Lib\site-packages\nltk\classify\__init__.py:97: in <module>
    from nltk.classify.scikitlearn import SklearnClassifier
C:\Users\USER\anaconda3\Lib\site-packages\nltk\classify\scikitlearn.py:38: in <module>
    from sklearn.feature_extraction import DictVectorizer
C:\Users\USER\anaconda3\Lib\site-packages\sklearn\__init__.py:87: in <module>
    from .base import clone
C:\Users\USER\anaconda3\Lib\site-packages\sklearn\base.py:19: in <module>
    from .utils import _IS_32BIT
C:\Users\USER\anaconda3\Lib\site-packages\sklearn\utils\__init__.py:28: in <module>
    from .murmurhash import murmurhash3_32
sklearn\\utils\\murmurhash.pyx:1: in init sklearn.utils.murmurhash
    ???
E   ValueError: numpy.dtype size changed, may indicate binary incompatibility. Expected 96 from C header, got 88 from PyObject
________________________________________________________________________________________ ERROR collecting tests/test_openai_model.py ________________________________________________________________________________________ 
tests\test_openai_model.py:8: in <module>
    from agents.custom_agent import CustomAgent
agents\custom_agent.py:1: in <module>
    from ai_engine.models.memory.context_manager import ContextManager
ai_engine\models\memory\__init__.py:2: in <module>
    from .memory_manager import MemoryManager
ai_engine\models\memory\memory_manager.py:4: in <module>
    import nltk
C:\Users\USER\anaconda3\Lib\site-packages\nltk\__init__.py:146: in <module>
    from nltk.chunk import *
C:\Users\USER\anaconda3\Lib\site-packages\nltk\chunk\__init__.py:155: in <module>
    from nltk.chunk.api import ChunkParserI
C:\Users\USER\anaconda3\Lib\site-packages\nltk\chunk\api.py:13: in <module>
    from nltk.chunk.util import ChunkScore
C:\Users\USER\anaconda3\Lib\site-packages\nltk\chunk\util.py:12: in <module>
    from nltk.tag.mapping import map_tag
C:\Users\USER\anaconda3\Lib\site-packages\nltk\tag\__init__.py:70: in <module>
    from nltk.tag.sequential import (
C:\Users\USER\anaconda3\Lib\site-packages\nltk\tag\sequential.py:26: in <module>
    from nltk.classify import NaiveBayesClassifier
C:\Users\USER\anaconda3\Lib\site-packages\nltk\classify\__init__.py:97: in <module>
    from nltk.classify.scikitlearn import SklearnClassifier
C:\Users\USER\anaconda3\Lib\site-packages\nltk\classify\scikitlearn.py:38: in <module>
    from sklearn.feature_extraction import DictVectorizer
C:\Users\USER\anaconda3\Lib\site-packages\sklearn\__init__.py:87: in <module>
    from .base import clone
C:\Users\USER\anaconda3\Lib\site-packages\sklearn\base.py:19: in <module>
    from .utils import _IS_32BIT
C:\Users\USER\anaconda3\Lib\site-packages\sklearn\utils\__init__.py:28: in <module>
    from .murmurhash import murmurhash3_32
sklearn\\utils\\murmurhash.pyx:1: in init sklearn.utils.murmurhash
    ???
E   ValueError: numpy.dtype size changed, may indicate binary incompatibility. Expected 96 from C header, got 88 from PyObject
================================================================================================== short test summary info ================================================================================================== 
ERROR tests/test_AgentActor.py - ValueError: numpy.dtype size changed, may indicate binary incompatibility. Expected 96 from C header, got 88 from PyObject
ERROR tests/test_agent_dispatcher.py
ERROR tests/test_agent_registry.py
ERROR tests/test_ai_confidence_manager.py
ERROR tests/test_ai_patch_optimizer.py
ERROR tests/test_ai_patch_retry_manager.py
ERROR tests/test_ai_patch_review_manager.py
ERROR tests/test_ai_rollback_analysis.py
ERROR tests/test_auto_fixer.py
ERROR tests/test_custom_agent.py
ERROR tests/test_debug_agent_auto_fixer.py
ERROR tests/test_debug_agent_utils.py
ERROR tests/test_debugger_agent.py
ERROR tests/test_debugger_cli.py
ERROR tests/test_debugger_core.py
ERROR tests/test_debugger_reporter.py
ERROR tests/test_debugger_runner.py - NameError: name 'Optional' is not defined
ERROR tests/test_deepseek_model.py
ERROR tests/test_dispatcher.py
ERROR tests/test_journal_agent.py - ValueError: numpy.dtype size changed, may indicate binary incompatibility. Expected 96 from C header, got 88 from PyObject
ERROR tests/test_openai_model.py - ValueError: numpy.dtype size changed, may indicate binary incompatibility. Expected 96 from C header, got 88 from PyObject
!!!!!!!!!!!!!!!!!!!!!!!!!!!!!!!!!!!!!!!!!!!!!!!!!!!!!!!!!!!!!!!!!!!!!!!!!!!!!!!!!!!!!!!!! Interrupted: 21 errors during collection !!!!!!!!!!!!!!!!!!!!!!!!!!!!!!!!!!!!!!!!!!!!!!!!!!!!!!!!!!!!!!!!!!!!!!!!!!!!!!!!!!!!!!!!!! 
==================================================================================================== 21 errors in 11.19s ==================================================================================================== 
(base) PS D:\side_projects\Side-projects\ai_agent_project> 